Workbook

Sheet Sheet1
A1: No. Pohon | B1: Nama Jenis | C1: Nama Latin | D1: Diameter | E1: Tinggi | F1: Berat Jenis | G1: AGB (kg) | H1: AGB (Ton) | I1: Cadangan Karbon (Ton C) | J1: Serapan Karbon (ton CO2e)
A2: 01 | B2: Ketapang kencana | C2: Terminalia mantaly | D2: 31.5 | E2: 14.5 | F2: 0.6 | G2: =0.11*F2*(D2^2.67) -> 660.74383 | H2: =G2/1000 -> 0.66074383 | I2: =H2*0.47 -> 0.3105496 | J2: =I2*(44/12) -> 1.1386819
A3: 02 | B3: Ketapang kencana | C3: Terminalia mantaly | D3: 27.4 | E3: 10.5 | F3: 0.6 | G3: =0.11*F3*(D3^2.67) -> 455.34224 | H3: =G3/1000 -> 0.45534224 | I3: =H3*0.47 -> 0.21401085 | J3: =I3*(44/12) -> 0.78470646
A4: 03 | B4: Ketapang kencana | C4: Terminalia mantaly | D4: 17.3 | E4: 7 | F4: 0.6 | G4: =0.11*F4*(D4^2.67) -> 133.39115 | H4: =G4/1000 -> 0.13339115 | I4: =H4*0.47 -> 0.062693843 | J4: =I4*(44/12) -> 0.22987742
A5: 04 | B5: Pulai | C5: Alstonia scholaris | D5: 37.5 | E5: 11 | F5: =VLOOKUP(C5,Sheet2!A4:B76,2,FALSE) -> 0.3973 | G5: =0.11*F5*(D5^2.67) -> 696.90685 | H5: =G5/1000 -> 0.69690685 | I5: =H5*0.47 -> 0.32754622 | J5: =I5*(44/12) -> 1.2010028
A6: 05 | B6: Ketapang kencana | C6: Terminalia mantaly | D6: 29.2 | E6: 12.3 | F6: 0.6 | G6: =0.11*F6*(D6^2.67) -> 539.65493 | H6: =G6/1000 -> 0.53965493 | I6: =H6*0.47 -> 0.25363782 | J6: =I6*(44/12) -> 0.93000533
A7: 06 | B7: Balangeran | C7: Shorea balangeran | D7: 8.2 | E7: 7.6 | F7: =VLOOKUP(C7,Sheet2!A6:B78,2,FALSE) -> 0.59 | G7: =0.11*F7*(D7^2.67) -> 17.870129 | H7: =G7/1000 -> 0.017870129 | I7: =H7*0.47 -> 0.0083989605 | J7: =I7*(44/12) -> 0.030796189
A8: 07 | B8: Balangeran | C8: Shorea balangeran | D8: 12.9 | E8: 11 | F8: =VLOOKUP(C8,Sheet2!A7:B79,2,FALSE) -> 0.59 | G8: =0.11*F8*(D8^2.67) -> 59.912746 | H8: =G8/1000 -> 0.059912746 | I8: =H8*0.47 -> 0.02815899 | J8: =I8*(44/12) -> 0.10324963
A9: 08 | B9: Eboni | C9: Diospyros celebica | D9: 37.6 | E9: 10 | F9: =VLOOKUP(C9,Sheet2!A8:B80,2,FALSE) -> 0.97 | G9: =0.11*F9*(D9^2.67) -> 1713.6257 | H9: =G9/1000 -> 1.7136257 | I9: =H9*0.47 -> 0.80540408 | J9: =I9*(44/12) -> 2.9531483
A10: 09 | B10: Balangeran | C10: Shorea balangeran | D10: 9.2 | E10: 11 | F10: =VLOOKUP(C10,Sheet2!A9:B81,2,FALSE) -> 0.59 | G10: =0.11*F10*(D10^2.67) -> 24.29731 | H10: =G10/1000 -> 0.02429731 | I10: =H10*0.47 -> 0.011419736 | J10: =I10*(44/12) -> 0.041872364
A11: 10 | B11: Mangga | C11: Mangifera indica | D11: 44.6 | E11: 12 | F11: =VLOOKUP(C11,Sheet2!A10:B82,2,FALSE) -> 0.5 | G11: =0.11*F11*(D11^2.67) -> 1393.4352 | H11: =G11/1000 -> 1.3934352 | I11: =H11*0.47 -> 0.65491452 | J11: =I11*(44/12) -> 2.4013532
A12: 11 | B12: Balangeran | C12: Shorea balangeran | D12: 9.7 | E12: 10.5 | F12: =VLOOKUP(C12,Sheet2!A11:B83,2,FALSE) -> 0.59 | G12: =0.11*F12*(D12^2.67) -> 27.984995 | H12: =G12/1000 -> 0.027984995 | I12: =H12*0.47 -> 0.013152947 | J12: =I12*(44/12) -> 0.048227474
A13: 12 | B13: Damar | C13: Agathis borneensis | D13: 14.5 | E13: 8.5 | F13: =VLOOKUP(C13,Sheet2!A12:B84,2,FALSE) -> 0.48 | G13: =0.11*F13*(D13^2.67) -> 66.60188 | H13: =G13/1000 -> 0.06660188 | I13: =H13*0.47 -> 0.031302884 | J13: =I13*(44/12) -> 0.11477724
A14: 13 | B14: Ketapang kencana | C14: Terminalia mantaly | D14: 12.6 | E14: 9 | F14: 0.6 | G14: =0.11*F14*(D14^2.67) -> 57.218081 | H14: =G14/1000 -> 0.057218081 | I14: =H14*0.47 -> 0.026892498 | J14: =I14*(44/12) -> 0.098605827
A15: 14 | B15: Kuku | C15: Pericopsis mooniana | D15: 50 | E15: 10.5 | F15: =VLOOKUP(C15,Sheet2!A14:B86,2,FALSE) -> 0.87 | G15: =0.11*F15*(D15^2.67) -> 3289.7421 | H15: =G15/1000 -> 3.2897421 | I15: =H15*0.47 -> 1.5461788 | J15: =I15*(44/12) -> 5.6693222
A16: 15 | B16: Kuku | C16: Pericopsis mooniana | D16: 31.5 | E16: 7.5 | F16: =VLOOKUP(C16,Sheet2!A15:B87,2,FALSE) -> 0.87 | G16: =0.11*F16*(D16^2.67) -> 958.07855 | H16: =G16/1000 -> 0.95807855 | I16: =H16*0.47 -> 0.45029692 | J16: =I16*(44/12) -> 1.6510887
A17: 16 | B17: Tanjung | C17: Mimusops elengi | D17: 25.2 | E17: 7 | F17: =VLOOKUP(C17,Sheet2!A16:B88,2,FALSE) -> 0.92 | G17: =0.11*F17*(D17^2.67) -> 558.36727 | H17: =G17/1000 -> 0.55836727 | I17: =H17*0.47 -> 0.26243262 | J17: =I17*(44/12) -> 0.96225294
A18: 17 | B18: Bintangur | C18: Calophyllum inophyllum | D18: 5.8 | E18: 4 | F18: 0.65 | G18: =0.11*F18*(D18^2.67) -> 7.8101394 | H18: =G18/1000 -> 0.0078101394 | I18: =H18*0.47 -> 0.0036707655 | J18: =I18*(44/12) -> 0.013459474
A19: 18 | B19: Meranti | C19: Shorea leprosula | D19: 4 | E19: 3.5 | F19: =VLOOKUP(C19,Sheet2!A18:B90,2,FALSE) -> 0.59 | G19: =0.11*F19*(D19^2.67) -> 2.6287233 | H19: =G19/1000 -> 0.0026287233 | I19: =H19*0.47 -> 0.0012354999 | J19: =I19*(44/12) -> 0.0045301665
A20: 19 | B20: Lengkeng | C20: Dimocarpis longan | D20: 7.2 | E20: 4 | F20: 0.7 | G20: =0.11*F20*(D20^2.67) -> 14.981955 | H20: =G20/1000 -> 0.014981955 | I20: =H20*0.47 -> 0.0070415189 | J20: =I20*(44/12) -> 0.025818903
A21: 20 | B21: Cemara laut | C21: Casuarina equisetifolia | D21: 14.5 | E21: 8 | F21: 0.8 | G21: =0.11*F21*(D21^2.67) -> 111.00313 | H21: =G21/1000 -> 0.11100313 | I21: =H21*0.47 -> 0.052171473 | J21: =I21*(44/12) -> 0.1912954
A22: 21 | B22: Mahoni | C22: Switenia mahagoni | D22: 6.6 | E22: 7.5 | F22: 0.64 | G22: =0.11*F22*(D22^2.67) -> 10.858128 | H22: =G22/1000 -> 0.010858128 | I22: =H22*0.47 -> 0.0051033203 | J22: =I22*(44/12) -> 0.018712174
A23: 22 | B23: Jambu bol | C23: Syzygium malaccense | D23: 22.2 | E23: 7.7 | F23: 0.55 | G23: =0.11*F23*(D23^2.67) -> 237.96759 | H23: =G23/1000 -> 0.23796759 | I23: =H23*0.47 -> 0.11184477 | J23: =I23*(44/12) -> 0.41009748
A24: 23 | B24: Mahoni | C24: Switenia mahagoni | D24: 9 | E24: 8.5 | F24: 0.64 | G24: =0.11*F24*(D24^2.67) -> 24.854221 | H24: =G24/1000 -> 0.024854221 | I24: =H24*0.47 -> 0.011681484 | J24: =I24*(44/12) -> 0.042832108
A25: 24 | B25: Meranti | C25: Shorea leprosula | D25: 2.4 | E25: 6.6 | F25: =VLOOKUP(C25,Sheet2!A24:B96,2,FALSE) -> 0.59 | G25: =0.11*F25*(D25^2.67) -> 0.67206103 | H25: =G25/1000 -> 0.00067206103 | I25: =H25*0.47 -> 0.00031586868 | J25: =I25*(44/12) -> 0.0011581852
A26: 25 | B26: Meranti | C26: Shorea leprosula | D26: 6.8 | E26: 4.5 | F26: =VLOOKUP(C26,Sheet2!A25:B97,2,FALSE) -> 0.59 | G26: =0.11*F26*(D26^2.67) -> 10.840355 | H26: =G26/1000 -> 0.010840355 | I26: =H26*0.47 -> 0.0050949667 | J26: =I26*(44/12) -> 0.018681545
A27: 26 | B27: Kapur | C27: Dryobalanops aromatica | D27: 6.4 | E27: 4 | F27: =VLOOKUP(C27,Sheet2!A26:B98,2,FALSE) -> 0.63 | G27: =0.11*F27*(D27^2.67) -> 9.8454091 | H27: =G27/1000 -> 0.0098454091 | I27: =H27*0.47 -> 0.0046273423 | J27: =I27*(44/12) -> 0.016966922
A28: 27 | B28: Balangeran | C28: Shorea balangeran | D28: 7.3 | E28: 6 | F28: =VLOOKUP(C28,Sheet2!A27:B99,2,FALSE) -> 0.59 | G28: =0.11*F28*(D28^2.67) -> 13.101371 | H28: =G28/1000 -> 0.013101371 | I28: =H28*0.47 -> 0.0061576442 | J28: =I28*(44/12) -> 0.022578029
A29: 30 | B29: Balangeran | C29: Shorea balangeran | D29: 28.1 | E29: 12 | F29: =VLOOKUP(C29,Sheet2!A28:B100,2,FALSE) -> 0.59 | G29: =0.11*F29*(D29^2.67) -> 478.95043 | H29: =G29/1000 -> 0.47895043 | I29: =H29*0.47 -> 0.2251067 | J29: =I29*(44/12) -> 0.82539125
A30: 31 | B30: Mahoni | C30: Switenia mahagoni | D30: 5.9 | E30: 5.5 | F30: 0.64 | G30: =0.11*F30*(D30^2.67) -> 8.0491038 | H30: =G30/1000 -> 0.0080491038 | I30: =H30*0.47 -> 0.0037830788 | J30: =I30*(44/12) -> 0.013871289
A31: 32 | B31: Durian | C31: Durio zibethinus | D31: 11.5 | E31: 2 | F31: =VLOOKUP(C31,Sheet2!A30:B102,2,FALSE) -> 0.56 | G31: =0.11*F31*(D31^2.67) -> 41.845036 | H31: =G31/1000 -> 0.041845036 | I31: =H31*0.47 -> 0.019667167 | J31: =I31*(44/12) -> 0.072112945
A32: 33 | B32: Gaharu | C32: Aquilaria malacensis | D32: 9.4 | E32: 6.6 | F32: 0.92 | G32: =0.11*F32*(D32^2.67) -> 40.126556 | H32: =G32/1000 -> 0.040126556 | I32: =H32*0.47 -> 0.018859481 | J32: =I32*(44/12) -> 0.069151431
A33: 34 | B33: Rambutan | C33: Nephelium lappaceum | D33: 11 | E33: 4 | F33: =VLOOKUP(C33,Sheet2!A32:B104,2,FALSE) -> 0.9 | G33: =0.11*F33*(D33^2.67) -> 59.724657 | H33: =G33/1000 -> 0.059724657 | I33: =H33*0.47 -> 0.028070589 | J33: =I33*(44/12) -> 0.10292549
A34: 35 | B34: Mangga | C34: Mangifera indica | D34: 2.3 | E34: 6 | F34: 0.5 | G34: =0.11*F34*(D34^2.67) -> 0.50836543 | H34: =G34/1000 -> 0.00050836543 | I34: =H34*0.47 -> 0.00023893175 | J34: =I34*(44/12) -> 0.00087608309
A35: 36 | B35: Sungkai | C35: Peronema canescens | D35: 8.6 | E35: 6 | F35: 588 | G35: =0.11*F35*(D35^2.67) -> 20224.644 | H35: =G35/1000 -> 20.224644 | I35: =H35*0.47 -> 9.5055825 | J35: =I35*(44/12) -> 34.853802
A36: 37 | B36: Balangeran | C36: Shorea balangeran | D36: 21.6 | E36: 10.5 | F36: =VLOOKUP(C36,Sheet2!A35:B107,2,FALSE) -> 0.59 | G36: =0.11*F36*(D36^2.67) -> 237.26638 | H36: =G36/1000 -> 0.23726638 | I36: =H36*0.47 -> 0.1115152 | J36: =I36*(44/12) -> 0.40888907
A37: 38 | B37: Kweni | C37: Mangifera odorata | D37: 35.6 | E37: 7 | F37: 0.5 | G37: =0.11*F37*(D37^2.67) -> 763.36841 | H37: =G37/1000 -> 0.76336841 | I37: =H37*0.47 -> 0.35878315 | J37: =I37*(44/12) -> 1.3155382
A38: 39 | B38: Kuku | C38: Pericopsis mooniana | D38: 21 | E38: 14 | F38: =VLOOKUP(C38,Sheet2!A37:B109,2,FALSE) -> 0.87 | G38: =0.11*F38*(D38^2.67) -> 324.517 | H38: =G38/1000 -> 0.324517 | I38: =H38*0.47 -> 0.15252299 | J38: =I38*(44/12) -> 0.55925097
A39: 40 | B39: Damar | C39: Agathis borneensis | D39: 18.8 | E39: 10 | F39: 0.48 | G39: =0.11*F39*(D39^2.67) -> 133.24023 | H39: =G39/1000 -> 0.13324023 | I39: =H39*0.47 -> 0.062622909 | J39: =I39*(44/12) -> 0.22961733
A40: 41
...

Sheet Sheet2
A1: Nama Jenis | B1: BJ
A2: Falcataria moluccana | B2: 0.3
A3: Duabanga moluccana | B3: 0.32
A4: Macaranga gigantea | B4: 0.32
A5: Macaranga sp. | B5: 0.32
A6: Campnosperma auriculata | B6: 0.327
A7: Prunus javanica | B7: 0.345
A8: Macaranga triloba | B8: 0.3533
A9: Archidendron bubalinum | B9: 0.38
A10: Dillenia suffruticosa | B10: 0.38
A11: Alstonia scholaris | B11: 0.3973
A12: Litsea firma | B12: 0.411
A13: Litsea sp. | B13: 0.411
... A73: Eusideroxylon zwageri | B73: 1.04
